File: N02D1045NM_1.csv
System ID,,"4483C1713"
Method name only,,"Compression_Cylindrical_Metallic_NEW"
Test type,,"Compression"
Sample file name,,"N02D1045NM"
Last test date,,"9/8/2025"
Last test time,,"5:12:49 PM"
Course,,"NPRE432"
Lab Section Number,,"02"
Group,,"D"
Material,,"Normalized 1045 steel"
Heat Treatment,,"NM"
Other Information,,""
Crosshead Speed,(mm/min),"2.50"
Geometry,,"Circular"
Diameter,(mm),"12.66"
Length,(mm),"39.95"
Extensometer Gage Length,(mm),"25.40"
Rockwell Hardness,,"91.5"
Rockwell Scale,,"HRB"
Final Diameter,,"12.94"
Final Length,,"38.29"
Final Specimen State,,""
Notes During Test,,""

Results Table 1
,,"1"
Maximum Force,(kN),"100.0"
Maximum Strain,(%),"1.497"

Time,Displacement,Force,Composite strain
(s),(mm),(kN),(mm/mm)
"0.00","0.00","-0.003658","0.01193"
"0.50","0.02","0.01257","0.01249"
"1.00","0.04","0.01453","0.01302"
"1.50","0.06","0.03479","0.01341"
"2.00","0.08","0.1065","0.01377"
"2.50","0.10","0.6614","0.01406"
"3.00","0.13","1.290","0.01419"
"3.50","0.15","1.828","0.01416"
"4.00","0.17","2.470","0.01419"
"4.50","0.19","3.192","0.01419"
"5.00","0.21","4.035","0.01419"
"5.50","0.23","4.978","0.01420"
"6.00","0.25","6.005","0.01420"
"6.50","0.27","7.134","0.01424"
"7.00","0.29","8.376","0.01429"
"7.50","0.31","9.700","0.01432"
"8.00","0.33","11.09","0.01436"
"8.50","0.35","12.54","0.01441"
"9.00","0.38","14.00","0.01445"
"9.50","0.40","15.52","0.01449"
"10.00","0.42","17.05","0.01453"
"10.50","0.44","18.62","0.01456"
"11.00","0.46","20.20","0.01458"
"11.50","0.48","21.80","0.01461"
"12.00","0.50","23.34","0.01464"
"12.50","0.52","24.96","0.01467"
"13.00","0.54","26.54","0.01469"
"13.50","0.56","28.16","0.01472"
"14.00","0.58","29.77","0.01474"
"14.50","0.60","31.41","0.01476"
"15.00","0.62","33.03","0.01477"
"15.50","0.65","34.68","0.01479"
"16.00","0.67","36.30","0.01480"
"16.50","0.69","37.94","0.01481"
"17.00","0.71","39.56","0.01482"
"17.50","0.73","41.19","0.01482"
"18.00","0.75","42.82","0.01481"
"18.50","0.77","44.45","0.01480"
"19.00","0.79","46.07","0.01478"
"19.50","0.81","47.69","0.01475"
"20.00","0.83","49.29","0.01471"
"20.50","0.85","50.86","0.01464"
"21.00","0.88","52.41","0.01451"
"21.50","0.90","53.80","0.01419"
"22.00","0.92","54.63","0.01323"
"22.50","0.94","54.32","0.01172"
"23.00","0.96","54.49","0.01091"
"23.50","0.98","54.79","0.01090"
"24.00","1.00","55.14","0.01061"
"24.50","1.02","55.53","0.01049"
"25.00","1.04","55.94","0.01040"
"25.50","1.06","56.32","0.01032"
"26.00","1.08","56.72","0.01027"
"26.50","1.10","57.06","0.01024"
"27.00","1.13","57.37","0.01023"
"27.50","1.15","57.11","0.01032"
"28.00","1.17","57.40","0.01052"
"28.50","1.19","58.08","0.01061"
"29.00","1.21","58.67","0.01061"
"29.50","1.23","59.26","0.01057"
"30.00","1.25","59.80","0.01050"
"30.50","1.27","60.35","0.01043"
"31.00","1.29","60.88","0.01038"
"31.50","1.31","61.43","0.01034"
"32.00","1.33","61.95","0.01031"
"32.50","1.35","62.49","0.01028"
"33.00","1.37","63.01","0.01025"
"33.50","1.40","63.55","0.01024"
"34.00","1.42","64.08","0.01021"
"34.50","1.44","64.61","0.01021"
"35.00","1.46","65.12","0.01022"
"35.50","1.48","65.64","0.01026"
"36.00","1.50","66.16","0.01033"
"36.50","1.52","66.66","0.01038"
"37.00","1.54","67.17","0.01040"
"37.50","1.56","67.67","0.01042"
"38.00","1.58","68.18","0.01043"
"38.50","1.60","68.67","0.01045"
"39.00","1.63","69.17","0.01046"
"39.50","1.65","69.66","0.01049"
"40.00","1.67","70.17","0.01052"
"40.50","1.69","70.65","0.01055"
"41.00","1.71","71.14","0.01057"
"41.50","1.73","71.61","0.01062"
"42.00","1.75","72.09","0.01064"
"42.50","1.77","72.56","0.01064"
"43.00","1.79","73.04","0.01064"
"43.50","1.81","73.51","0.01065"
"44.00","1.83","73.98","0.01066"
"44.50","1.85","74.44","0.01067"
"45.00","1.88","74.90","0.01067"
"45.50","1.90","75.35","0.01068"
"46.00","1.92","75.79","0.01069"
"46.50","1.94","76.24","0.01071"
"47.00","1.96","76.69","0.01074"
"47.50","1.98","77.14","0.01075"
"48.00","2.00","77.58","0.01075"
"48.50","2.02","78.02","0.01076"
"49.00","2.04","78.45","0.01075"
"49.50","2.06","78.87","0.01077"
"50.00","2.08","79.29","0.01079"
"50.50","2.10","79.72","0.01081"
"51.00","2.12","80.14","0.01084"
"51.50","2.15","80.59","0.01083"
"52.00","2.17","81.02","0.01087"
"52.50","2.19","81.46","0.01103"
"53.00","2.21","81.88","0.01119"
"53.50","2.23","82.30","0.01135"
"54.00","2.25","82.72","0.01151"
"54.50","2.27","83.13","0.01166"
"55.00","2.29","83.53","0.01181"
"55.50","2.31","83.94","0.01195"
"56.00","2.33","84.35","0.01208"
"56.50","2.35","84.76","0.01222"
"57.00","2.38","85.16","0.01234"
"57.50","2.40","85.56","0.01246"
"58.00","2.42","85.96","0.01256"
"58.50","2.44","86.35","0.01267"
"59.00","2.46","86.74","0.01278"
"59.50","2.48","87.13","0.01287"
"60.00","2.50","87.51","0.01294"
"60.50","2.52","87.89","0.01302"
"61.00","2.54","88.28","0.01309"
"61.50","2.56","88.65","0.01318"
"62.00","2.58","89.02","0.01326"
"62.50","2.60","89.40","0.01334"
"63.00","2.63","89.75","0.01341"
"63.50","2.65","90.11","0.01349"
"64.00","2.67","90.47","0.01358"
"64.50","2.69","90.82","0.01367"
"65.00","2.71","91.17","0.01374"
"65.50","2.73","91.54","0.01381"
"66.00","2.75","91.88","0.01387"
"66.50","2.77","92.24","0.01390"
"67.00","2.79","92.58","0.01395"
"67.50","2.81","92.91","0.01402"
"68.00","2.83","93.25","0.01408"
"68.50","2.85","93.58","0.01413"
"69.00","2.88","93.91","0.01419"
"69.50","2.90","94.25","0.01422"
"70.00","2.92","94.57","0.01426"
"70.50","2.94","94.90","0.01430"
"71.00","2.96","95.23","0.01432"
"71.50","2.98","95.54","0.01437"
"72.00","3.00","95.86","0.01440"
"72.50","3.02","96.17","0.01446"
"73.00","3.04","96.48","0.01451"
"73.50","3.06","96.78","0.01457"
"74.00","3.08","97.09","0.01463"
"74.50","3.10","97.39","0.01467"
"75.00","3.13","97.70","0.01470"
"75.50","3.15","98.00","0.01471"
"76.00","3.17","98.30","0.01473"
"76.50","3.19","98.59","0.01476"
"77.00","3.21","98.88","0.01480"
"77.50","3.23","99.16","0.01484"
"78.00","3.25","99.44","0.01488"
"78.50","3.27","99.73","0.01493"
"78.97","3.29","100.0","0.01497"