File: L2D/N02DBR_1.csv
System ID,,"4483C1713"
Method name only,,"Tension_Round_Reversals_Brass_NEW"
Test type,,"Tension TestProfiler"
Sample file name,,"N02DBR"
Last test date,,"9/15/2025"
Last test time,,"5:43:35 PM"
Course,,"NPRE432"
Lab Section Number,,"02"
Group,,"D"
Material,,"Brass"
Heat Treatment,,""
Other Information,,""
Geometry,,"Circular"
Gage Diameter,(mm),"7.20"
Grip Diameter,(mm),"12.84"
Rockwell Hardness,,"50.9"
Rockwell Scale,,"HRB"
Extensometer Gage Length,(mm),"25.40"
Final Gage Diameter (at Neck),(mm),"4.42"
Uniform Gage Diameter in mm (away from Neck),,"6.67"
Final Hardness at Uniform Gage Diameter,,"68.6"
Rockwell Scale,,"HRB"
Fracture Notes and Location,,""
Notes During Test,,""

Results Table 1
,,"1"
Maximum Force,(kN),"14.61"
Maximum Strain,(%),"35.03"

Time,Displacement,Force,Strain 1
(s),(mm),(kN),(mm/mm)
"0.00","0.00","0.1734","-0.00001285"
"0.50","0.03","0.7733","0.0002279"
"1.00","0.07","1.433","0.0004965"
"1.50","0.10","2.051","0.0007097"
"2.00","0.13","2.630","0.0009449"
"2.50","0.17","3.171","0.001153"
"3.00","0.20","3.683","0.001342"
"3.50","0.23","4.180","0.001534"
"4.00","0.27","4.656","0.001714"
"4.40","0.29","5.000","0.001849"
"4.40","0.29","5.002","0.001844"
"4.51","0.30","5.100","0.001901"
"5.01","0.27","4.352","0.001590"
"5.51","0.23","3.556","0.001267"
"6.01","0.20","2.828","0.0009816"
"6.51","0.17","2.143","0.0006989"
"7.01","0.13","1.483","0.0004386"
"7.40","0.11","0.9993","0.0002404"
"7.40","0.11","0.9968","0.0002329"
"7.40","0.11","0.9942","0.0002276"
"7.90","0.14","1.592","0.0004633"
"8.40","0.18","2.335","0.0007572"
"8.90","0.21","3.041","0.001040"
"9.40","0.24","3.746","0.001293"
"9.90","0.28","4.452","0.001572"
"10.40","0.31","5.122","0.001820"
"10.90","0.34","5.560","0.002006"
"11.40","0.38","5.921","0.002153"
"11.90","0.41","6.256","0.002312"
"12.40","0.44","6.575","0.002460"
"12.90","0.48","6.885","0.002625"
"13.40","0.51","7.172","0.002791"
"13.90","0.54","7.444","0.002944"
"14.40","0.58","7.699","0.003104"
"14.90","0.61","7.935","0.003268"
"15.40","0.64","8.169","0.003444"
"15.90","0.68","8.397","0.003612"
"16.40","0.71","8.624","0.003794"
"16.90","0.74","8.844","0.004006"
"17.40","0.78","9.053","0.004230"
"17.90","0.81","9.250","0.004489"
"18.40","0.84","9.434","0.004783"
"18.90","0.88","9.595","0.005107"
"19.40","0.91","9.737","0.005462"
"19.90","0.94","9.862","0.005861"
"20.40","0.98","9.964","0.006336"
"20.90","1.01","10.06","0.006831"
"21.40","1.04","10.14","0.007393"
"21.90","1.08","10.20","0.007965"
"22.40","1.11","10.27","0.008558"
"22.90","1.14","10.33","0.009160"
"23.40","1.18","10.38","0.009769"
"23.90","1.21","10.44","0.01042"
"24.40","1.24","10.48","0.01105"
"24.90","1.28","10.53","0.01171"
"25.40","1.31","10.58","0.01235"
"25.90","1.34","10.62","0.01299"
"26.40","1.38","10.66","0.01365"
"26.90","1.41","10.71","0.01431"
"27.40","1.44","10.75","0.01497"
"27.90","1.48","10.79","0.01563"
"28.40","1.51","10.83","0.01630"
"28.90","1.54","10.87","0.01696"
"29.40","1.58","10.90","0.01762"
"29.90","1.61","10.94","0.01830"
"30.40","1.64","10.98","0.01895"
"30.90","1.68","11.01","0.01963"
"31.17","1.69","11.03","0.02000"
"31.18","1.69","11.03","0.02000"
"31.25","1.70","11.04","0.02010"
"31.75","1.67","10.26","0.01993"
"32.25","1.63","9.504","0.01960"
"32.75","1.60","8.800","0.01930"
"33.25","1.56","8.104","0.01899"
"33.75","1.53","7.423","0.01869"
"34.25","1.50","6.757","0.01838"
"34.75","1.46","6.097","0.01807"
"35.25","1.43","5.462","0.01776"
"35.75","1.40","4.883","0.01747"
"36.25","1.36","4.449","0.01724"
"36.75","1.33","4.132","0.01707"
"37.25","1.30","3.847","0.01691"
"37.75","1.26","3.586","0.01676"
"38.25","1.23","3.332","0.01661"
"38.75","1.20","3.060","0.01646"
"39.25","1.16","2.786","0.01631"
"39.75","1.13","2.501","0.01615"
"40.25","1.10","2.128","0.01594"
"40.75","1.06","1.721","0.01570"
"41.25","1.03","1.306","0.01546"
"41.62","1.01","0.9987","0.01527"
"41.63","1.01","0.9970","0.01527"
"41.63","1.01","0.9954","0.01527"
"42.13","1.04","1.629","0.01551"
"42.63","1.07","2.349","0.01580"
"43.13","1.11","3.035","0.01611"
"43.63","1.14","3.707","0.01638"
"44.13","1.17","4.371","0.01667"
"44.63","1.21","5.018","0.01695"
"45.13","1.24","5.624","0.01722"
"45.63","1.27","6.184","0.01751"
"46.13","1.31","6.692","0.01774"
"46.63","1.34","7.129","0.01795"
"47.13","1.37","7.545","0.01815"
"47.63","1.41","7.946","0.01836"
"48.13","1.44","8.335","0.01857"
"48.63","1.47","8.695","0.01874"
"49.13","1.51","9.078","0.01894"
"49.63","1.54","9.440","0.01914"
"50.13","1.57","9.783","0.01933"
"50.63","1.61","10.12","0.01953"
"51.13","1.64","10.45","0.01971"
"51.63","1.67","10.75","0.01992"
"52.13","1.71","11.01","0.02014"
"52.63","1.74","11.20","0.02035"
"53.13","1.77","11.18","0.02079"
"53.63","1.81","11.15","0.02130"
"54.13","1.84","11.14","0.02211"
"54.63","1.87","11.17","0.02308"
"55.13","1.91","11.21","0.02403"
"55.63","1.94","11.24","0.02479"
"56.13","1.97","11.27","0.02533"
"56.63","2.01","11.30","0.02588"
"57.13","2.04","11.33","0.02661"
"57.63","2.07","11.36","0.02742"
"58.13","2.11","11.40","0.02817"
"58.63","2.14","11.42","0.02882"
"59.13","2.17","11.45","0.02941"
"59.63","2.21","11.48","0.03005"
"60.13","2.24","11.51","0.03080"
"60.63","2.27","11.54","0.03156"
"61.13","2.31","11.57","0.03226"
"61.63","2.34","11.60","0.03290"
"62.13","2.37","11.63","0.03348"
"62.63","2.41","11.65","0.03413"
"63.13","2.44","11.67","0.03488"
"63.63","2.47","11.70","0.03566"
"64.13","2.51","11.73","0.03642"
"64.63","2.54","11.75","0.03707"
"65.13","2.57","11.78","0.03760"
"65.63","2.61","11.81","0.03816"
"66.13","2.64","11.83","0.03884"
"66.63","2.67","11.85","0.03969"
"67.13","2.71","11.88","0.04059"
"67.63","2.74","11.91","0.04139"
"68.13","2.77","11.92","0.04199"
"68.63","2.81","11.95","0.04241"
"69.13","2.84","11.98","0.04280"
"69.63","2.87","12.01","0.04332"
"70.13","2.91","12.02","0.04409"
"70.63","2.94","12.02","0.04510"
"71.13","2.97","12.07","0.04615"
"71.63","3.01","12.12","0.04714"
"72.13","3.04","12.13","0.04808"
"72.63","3.07","12.13","0.04876"
"73.13","3.11","12.12","0.04911"
"73.63","3.14","12.17","0.04932"
"74.13","3.17","12.22","0.04956"
"74.63","3.21","12.25","0.04993"
"75.13","3.24","12.27","0.05056"
"75.63","3.27","12.28","0.05142"
"76.13","3.31","12.29","0.05246"
"76.63","3.34","12.25","0.05368"
"77.13","3.37","12.34","0.05473"
"77.63","3.41","12.39","0.05577"
"78.13","3.44","12.42","0.05675"
"78.63","3.47","12.42","0.05749"
"79.13","3.51","12.40","0.05780"
"79.63","3.54","12.42","0.05799"
"80.13","3.57","12.43","0.05819"
"80.63","3.61","12.44","0.05888"
"81.13","3.64","12.50","0.05967"
"81.63","3.67","12.55","0.06043"
"82.13","3.71","12.57","0.06108"
"82.63","3.74","12.58","0.06190"
"83.13","3.77","12.58","0.06296"
"83.63","3.81","12.59","0.06410"
"84.13","3.84","12.60","0.06519"
"84.63","3.87","12.61","0.06586"
"85.13","3.91","12.60","0.06604"
"85.63","3.94","12.68","0.06613"
"86.13","3.97","12.75","0.06628"
"86.63","4.01","12.77","0.06670"
"87.13","4.04","12.78","0.06761"
"87.63","4.07","12.78","0.06872"
"88.13","4.11","12.78","0.06988"
"88.63","4.14","12.76","0.07106"
"89.13","4.17","12.74","0.07230"
"89.63","4.21","12.73","0.07328"
"90.13","4.24","12.73","0.07375"
"90.63","4.27","12.78","0.07388"
"91.13","4.31","12.86","0.07408"
"91.63","4.34","12.90","0.07458"
"92.13","4.37","12.93","0.07549"
"92.63","4.41","12.95","0.07656"
"93.13","4.44","12.97","0.07767"
"93.63","4.47","12.98","0.07883"
"94.12","4.51","12.98","0.08000"
"94.12","4.51","12.98","0.08000"
"94.15","4.51","12.98","0.08006"
"94.65","4.48","12.24","0.08002"
"95.15","4.44","11.50","0.07966"
"95.65","4.41","10.82","0.07934"
"96.15","4.37","10.17","0.07902"
"96.65","4.34","9.521","0.07869"
"97.15","4.31","8.892","0.07837"
"97.65","4.27","8.272","0.07805"
"98.15","4.24","7.658","0.07771"
"98.65","4.21","7.060","0.07737"
"99.15","4.17","6.466","0.07703"
"99.65","4.14","5.902","0.07670"
"100.15","4.11","5.423","0.07641"
"100.65","4.07","5.051","0.07617"
"101.15","4.04","4.738","0.07596"
"101.65","4.01","4.476","0.07579"
"102.15","3.97","4.232","0.07562"
"102.65","3.94","4.011","0.07548"
"103.15","3.91","3.799","0.07534"
"103.65","3.87","3.593","0.07520"
"104.15","3.84","3.395","0.07507"
"104.65","3.81","3.204","0.07494"
"105.15","3.77","2.997","0.07481"
"105.65","3.74","2.790","0.07467"
"106.15","3.71","2.581","0.07452"
"106.65","3.67","2.358","0.07437"
"107.15","3.64","2.131","0.07421"
"107.65","3.61","1.840","0.07400"
"108.15","3.57","1.500","0.07376"
"108.65","3.54","1.154","0.07348"
"108.86","3.53","0.9991","0.07337"
"108.86","3.53","0.9976","0.07336"
"108.87","3.53","0.9962","0.07336"
"109.37","3.56","1.601","0.07362"
"109.87","3.59","2.278","0.07394"
"110.37","3.63","2.921","0.07426"
"110.87","3.66","3.564","0.07457"
"111.37","3.69","4.190","0.07488"
"111.87","3.73","4.793","0.07519"
"112.37","3.76","5.361","0.07548"
"112.87","3.79","5.853","0.07575"
"113.37","3.83","6.292","0.07600"
"113.87","3.86","6.681","0.07621"
"114.37","3.89","7.055","0.07642"
"114.87","3.93","7.432","0.07662"
"115.37","3.96","7.797","0.07683"
"115.87","3.99","8.150","0.07703"
"116.37","4.03","8.492","0.07722"
"116.87","4.06","8.842","0.07743"
"117.37","4.09","9.180","0.07762"
"117.87","4.13","9.502","0.07781"
"118.37","4.16","9.830","0.07801"
"118.87","4.19","10.15","0.07821"
"119.37","4.23","10.48","0.07841"
"119.87","4.26","10.80","0.07862"
"120.37","4.29","11.11","0.07882"
"120.87","4.33","11.43","0.07903"
"121.37","4.36","11.74","0.07925"
"121.87","4.39","12.04","0.07946"
"122.37","4.43","12.30","0.07965"
"122.87","4.46","12.58","0.07986"
"123.37","4.49","12.84","0.08009"
"123.87","4.53","13.06","0.08032"
"124.37","4.56","12.96","0.08055"
"124.87","4.59","12.95","0.08058"
"125.37","4.63","12.95","0.08070"
"125.87","4.66","12.94","0.08123"
"126.37","4.69","12.99","0.08205"
"126.87","4.73","13.04","0.08292"
"127.37","4.76","13.08","0.08375"
"127.87","4.79","13.11","0.08437"
"128.37","4.83","13.12","0.08475"
"128.87","4.86","13.16","0.08526"
"129.37","4.89","13.17","0.08625"
"129.87","4.93","13.17","0.08738"
"130.37","4.96","13.17","0.08859"
"130.87","4.99","13.16","0.08983"
"131.37","5.03","13.14","0.09111"
"131.87","5.06","13.12","0.09231"
"132.37","5.09","13.11","0.09311"
"132.87","5.13","13.09","0.09349"
"133.37","5.16","13.08","0.09358"
"133.87","5.19","13.17","0.09367"
"134.37","5.23","13.24","0.09386"
"134.87","5.26","13.27","0.09434"
"135.37","5.29","13.30","0.09518"
"135.87","5.33","13.33","0.09618"
"136.37","5.36","13.35","0.09727"
"136.87","5.39","13.37","0.09840"
"137.37","5.43","13.38","0.09956"
"137.87","5.46","13.38","0.1008"
"138.37","5.49","13.33","0.1021"
"138.87","5.53","13.30","0.1031"
"139.37","5.56","13.32","0.1037"
"139.87","5.59","13.35","0.1040"
"140.37","5.63","13.36","0.1041"
"140.87","5.66","13.38","0.1042"
"141.37","5.69","13.48","0.1043"
"141.87","5.73","13.51","0.1044"
"142.37","5.76","13.50","0.1050"
"142.87","5.79","13.51","0.1060"
"143.37","5.83","13.54","0.1071"
"143.87","5.86","13.57","0.1082"
"144.37","5.89","13.58","0.1094"
"144.87","5.93","13.58","0.1106"
"145.37","5.96","13.57","0.1118"
"145.87","5.99","13.55","0.1131"
"146.37","6.03","13.53","0.1143"
"146.87","6.06","13.50","0.1152"
"147.37","6.09","13.48","0.1156"
"147.87","6.13","13.46","0.1156"
"148.37","6.16","13.56","0.1157"
"148.87","6.19","13.62","0.1159"
"149.37","6.23","13.66","0.1162"
"149.87","6.26","13.69","0.1169"
"150.37","6.29","13.72","0.1178"
"150.87","6.33","13.74","0.1188"
"151.37","6.36","13.76","0.1199"
"151.87","6.39","13.77","0.1211"
"152.37","6.43","13.78","0.1222"
"152.87","6.46","13.78","0.1234"
"153.37","6.49","13.78","0.1246"
"153.87","6.53","13.76","0.1259"
"154.37","6.56","13.74","0.1271"
"154.87","6.59","13.72","0.1280"
"155.37","6.63","13.72","0.1285"
"155.87","6.66","13.72","0.1287"
"156.37","6.69","13.70","0.1287"
"156.87","6.73","13.72","0.1288"
"157.37","6.76","13.82","0.1288"
"157.87","6.79","13.87","0.1289"
"158.37","6.83","13.89","0.1291"
"158.87","6.86","13.90","0.1296"
"159.37","6.89","13.92","0.1305"
"159.87","6.93","13.94","0.1316"
"160.37","6.96","13.95","0.1327"
"160.87","6.99","13.96","0.1339"
"161.37","7.03","13.97","0.1351"
"161.87","7.06","13.97","0.1363"
"162.37","7.09","13.97","0.1376"
"162.87","7.13","13.96","0.1388"
"163.37","7.16","13.95","0.1401"
"163.87","7.19","13.93","0.1413"
"164.37","7.23","13.91","0.1425"
"164.87","7.26","13.88","0.1432"
"165.37","7.29","13.86","0.1435"
"165.87","7.33","13.84","0.1436"
"166.37","7.36","13.89","0.1436"
"166.87","7.39","13.98","0.1437"
"167.37","7.43","14.02","0.1439"
"167.87","7.46","14.05","0.1443"
"168.37","7.49","14.07","0.1449"
"168.87","7.53","14.09","0.1459"
"169.37","7.56","14.11","0.1470"
"169.87","7.59","14.13","0.1481"
"170.37","7.63","14.14","0.1493"
"170.87","7.66","14.15","0.1505"
"171.37","7.69","14.15","0.1517"
"171.87","7.73","14.15","0.1530"
"172.37","7.76","14.15","0.1542"
"172.87","7.79","14.14","0.1554"
"173.37","7.83","14.14","0.1567"
"173.87","7.86","14.13","0.1580"
"174.37","7.89","14.11","0.1590"
"174.87","7.93","14.10","0.1597"
"175.37","7.96","14.09","0.1600"
"175.87","7.99","14.08","0.1601"
"176.37","8.03","14.06","0.1601"
"176.87","8.06","14.06","0.1602"
"177.37","8.09","14.16","0.1602"
"177.87","8.13","14.21","0.1603"
"178.37","8.16","14.23","0.1603"
"178.87","8.19","14.25","0.1606"
"179.37","8.23","14.27","0.1612"
"179.87","8.26","14.28","0.1620"
"180.37","8.29","14.29","0.1631"
"180.87","8.33","14.30","0.1643"
"181.37","8.36","14.31","0.1655"
"181.87","8.39","14.31","0.1667"
"182.37","8.43","14.31","0.1680"
"182.87","8.46","14.31","0.1692"
"183.37","8.49","14.31","0.1705"
"183.87","8.53","14.30","0.1717"
"184.37","8.56","14.30","0.1730"
"184.87","8.59","14.30","0.1743"
"185.37","8.63","14.29","0.1756"
"185.87","8.66","14.28","0.1768"
"186.37","8.69","14.26","0.1779"
"186.87","8.73","14.24","0.1786"
"187.37","8.76","14.23","0.1791"
"187.87","8.79","14.21","0.1792"
"188.37","8.83","14.19","0.1793"
"188.87","8.86","14.25","0.1793"
"189.37","8.89","14.32","0.1794"
"189.87","8.93","14.35","0.1795"
"190.37","8.96","14.37","0.1799"
"190.87","8.99","14.39","0.1804"
"191.37","9.03","14.41","0.1813"
"191.87","9.06","14.42","0.1824"
"192.37","9.09","14.43","0.1835"
"192.87","9.13","14.43","0.1847"
"193.37","9.16","14.44","0.1860"
"193.87","9.19","14.44","0.1872"
"194.37","9.23","14.44","0.1885"
"194.87","9.26","14.44","0.1898"
"195.37","9.29","14.44","0.1910"
"195.87","9.33","14.44","0.1923"
"196.37","9.36","14.44","0.1935"
"196.87","9.39","14.44","0.1948"
"197.37","9.43","14.44","0.1961"
"197.87","9.46","14.45","0.1973"
"198.37","9.49","14.44","0.1986"
"198.87","9.53","14.44","0.1997"
"199.37","9.56","14.44","0.2007"
"199.87","9.59","14.43","0.2014"
"200.37","9.63","14.42","0.2017"
"200.87","9.66","14.41","0.2019"
"201.37","9.69","14.40","0.2020"
"201.87","9.73","14.40","0.2020"
"202.37","9.76","14.40","0.2020"
"202.87","9.79","14.47","0.2020"
"203.37","9.83","14.52","0.2021"
"203.87","9.86","14.53","0.2021"
"204.37","9.89","14.54","0.2023"
"204.87","9.93","14.55","0.2027"
"205.37","9.96","14.55","0.2034"
"205.87","9.99","14.56","0.2043"
"206.37","10.03","14.56","0.2054"
"206.87","10.06","14.55","0.2066"
"207.37","10.09","14.55","0.2079"
"207.87","10.13","14.54","0.2091"
"208.37","10.16","14.53","0.2104"
"208.87","10.19","14.52","0.2117"
"209.37","10.23","14.52","0.2130"
"209.87","10.26","14.51","0.2142"
"210.37","10.29","14.51","0.2155"
"210.87","10.33","14.52","0.2168"
"211.37","10.36","14.52","0.2180"
"211.87","10.39","14.52","0.2193"
"212.37","10.43","14.52","0.2206"
"212.87","10.46","14.53","0.2219"
"213.37","10.49","14.53","0.2231"
"213.87","10.53","14.53","0.2244"
"214.37","10.56","14.53","0.2257"
"214.87","10.59","14.53","0.2270"
"215.37","10.63","14.52","0.2281"
"215.87","10.66","14.52","0.2291"
"216.37","10.69","14.52","0.2299"
"216.87","10.73","14.51","0.2304"
"217.37","10.76","14.50","0.2307"
"217.87","10.79","14.50","0.2309"
"218.37","10.83","14.51","0.2309"
"218.87","10.86","14.52","0.2310"
"219.37","10.89","14.57","0.2310"
"219.87","10.93","14.61","0.2311"
"220.37","10.96","14.60","0.2313"
"220.87","10.99","14.60","0.2317"
"221.37","11.03","14.60","0.2324"
"221.87","11.06","14.60","0.2334"
"222.37","11.09","14.59","0.2345"
"222.87","11.13","14.59","0.2357"
"223.37","11.16","14.58","0.2370"
"223.87","11.19","14.57","0.2382"
"224.37","11.23","14.56","0.2395"
"224.87","11.26","14.56","0.2408"
"225.37","11.29","14.55","0.2421"
"225.87","11.33","14.54","0.2434"
"226.37","11.36","14.53","0.2447"
"226.87","11.39","14.52","0.2460"
"227.37","11.43","14.52","0.2473"
"227.87","11.46","14.52","0.2486"
"228.37","11.49","14.51","0.2498"
"228.87","11.53","14.51","0.2511"
"229.37","11.56","14.51","0.2524"
"229.87","11.59","14.50","0.2537"
"230.37","11.63","14.49","0.2550"
"230.87","11.66","14.48","0.2563"
"231.37","11.69","14.47","0.2576"
"231.87","11.73","14.47","0.2589"
"232.37","11.76","14.46","0.2602"
"232.87","11.79","14.45","0.2615"
"233.37","11.83","14.43","0.2628"
"233.87","11.86","14.42","0.2641"
"234.37","11.89","14.41","0.2654"
"234.87","11.93","14.39","0.2667"
"235.37","11.96","14.38","0.2680"
"235.87","11.99","14.36","0.2693"
"236.37","12.03","14.34","0.2706"
"236.87","12.06","14.32","0.2720"
"237.37","12.09","14.31","0.2733"
"237.87","12.13","14.29","0.2746"
"238.37","12.16","14.26","0.2759"
"238.87","12.19","14.24","0.2773"
"239.37","12.23","14.22","0.2786"
"239.87","12.26","14.20","0.2799"
"240.37","12.29","14.17","0.2812"
"240.87","12.33","14.14","0.2826"
"241.37","12.36","14.12","0.2839"
"241.87","12.39","14.09","0.2852"
"242.37","12.43","14.06","0.2866"
"242.87","12.46","14.03","0.2879"
"243.37","12.49","14.00","0.2893"
"243.87","12.53","13.97","0.2906"
"244.37","12.56","13.94","0.2919"
"244.87","12.59","13.91","0.2933"
"245.37","12.63","13.87","0.2946"
"245.87","12.66","13.84","0.2960"
"246.37","12.69","13.80","0.2973"
"246.87","12.73","13.76","0.2987"
"247.37","12.76","13.72","0.3000"
"247.87","12.79","13.68","0.3014"
"248.37","12.83","13.64","0.3027"
"248.87","12.86","13.60","0.3041"
"249.37","12.89","13.56","0.3054"
"249.87","12.93","13.52","0.3068"
"250.37","12.96","13.47","0.3082"
"250.87","12.99","13.43","0.3095"
"251.37","13.03","13.38","0.3109"
"251.87","13.06","13.33","0.3123"
"252.37","13.09","13.28","0.3136"
"252.87","13.13","13.23","0.3150"
"253.37","13.16","13.19","0.3164"
"253.87","13.19","13.13","0.3178"
"254.37","13.23","13.08","0.3191"
"254.87","13.26","13.02","0.3205"
"255.37","13.29","12.97","0.3219"
"255.87","13.33","12.91","0.3233"
"256.37","13.36","12.85","0.3247"
"256.87","13.39","12.79","0.3261"
"257.37","13.43","12.73","0.3275"
"257.87","13.46","12.67","0.3289"
"258.37","13.49","12.60","0.3303"
"258.87","13.53","12.54","0.3317"
"259.37","13.56","12.47","0.3331"
"259.87","13.59","12.40","0.3345"
"260.37","13.63","12.33","0.3359"
"260.87","13.66","12.26","0.3374"
"261.37","13.69","12.19","0.3388"
"261.87","13.73","12.11","0.3402"
"262.37","13.76","12.03","0.3416"
"262.87","13.79","11.95","0.3431"
"263.37","13.83","11.87","0.3445"
"263.87","13.86","11.78","0.3459"
"264.37","13.89","11.69","0.3474"
"264.87","13.93","11.60","0.3488"
"265.37","13.96","11.48","0.3503"
"265.41","13.96","6.263","0.3490"