File: L2D/N02D1045NM_1.csv
System ID,,"4483C1713"
Method name only,,"Tension_Round_NEW"
Test type,,"Tension"
Sample file name,,"N02D1045NM"
Last test date,,"9/15/2025"
Last test time,,"4:49:42 PM"
Course,,"NPRE432"
Lab Section Number,,"02"
Group,,"D"
Material,,"1045"
Heat Treatment,,"NM"
Other Information,,""
Crosshead Speed,(mm/min),"4.00"
Geometry,,"Circular"
Gage Diameter,(mm),"7.16"
Grip Diameter,(mm),"12.52"
Rockwell Hardness,,"87.1"
Rockwell Scale,,"HRB"
Extensometer Gage Length,(mm),"25.40"
Final Gage Diameter,(mm),"4.88"
Fracture Notes and Location,,""
Notes During Test,,""

Results Table 1
,,"1"
Maximum Force,(kN),"29.44"
Maximum Strain,(%),"30.57"

Time,Displacement,Force,Strain 1
(s),(mm),(kN),(mm/mm)
"0.00","0.00","0.2355","-0.00005530"
"0.50","0.03","1.122","0.00006040"
"1.00","0.07","2.122","0.0001794"
"1.50","0.10","2.941","0.0002665"
"2.00","0.13","3.661","0.0003673"
"2.50","0.17","4.318","0.0004396"
"3.00","0.20","4.911","0.0005105"
"3.50","0.23","5.417","0.0005786"
"4.00","0.27","5.850","0.0006291"
"4.50","0.30","6.260","0.0006840"
"5.00","0.33","6.646","0.0007408"
"5.50","0.37","7.004","0.0007884"
"6.00","0.40","7.344","0.0008289"
"6.50","0.43","7.664","0.0008729"
"7.00","0.47","7.975","0.0009099"
"7.50","0.50","8.289","0.0009387"
"8.00","0.53","8.605","0.0009825"
"8.50","0.57","8.919","0.001022"
"9.00","0.60","9.239","0.001047"
"9.50","0.63","9.548","0.001099"
"10.00","0.67","9.848","0.001138"
"10.50","0.70","10.14","0.001185"
"11.00","0.73","10.43","0.001211"
"11.50","0.77","10.71","0.001244"
"12.00","0.80","10.99","0.001275"
"12.50","0.83","11.25","0.001309"
"13.00","0.87","11.51","0.001351"
"13.50","0.90","11.78","0.001375"
"14.00","0.93","12.04","0.001407"
"14.50","0.97","12.31","0.001444"
"15.00","1.00","12.57","0.001492"
"15.50","1.03","12.83","0.001509"
"16.00","1.07","13.11","0.001549"
"16.50","1.10","13.37","0.001588"
"17.00","1.13","13.64","0.001612"
"17.50","1.17","13.91","0.001662"
"18.00","1.20","14.18","0.001691"
"18.50","1.23","14.43","0.001678"
"19.00","1.27","14.70","0.001709"
"19.50","1.30","14.98","0.001753"
"20.00","1.33","15.26","0.001792"
"20.50","1.37","15.54","0.001819"
"21.00","1.40","15.82","0.001862"
"21.50","1.43","16.09","0.001896"
"22.00","1.47","16.37","0.001940"
"22.50","1.50","16.65","0.001975"
"23.00","1.53","16.94","0.002019"
"23.50","1.57","17.22","0.002051"
"24.00","1.60","17.50","0.002089"
"24.50","1.63","17.79","0.002124"
"25.00","1.67","18.07","0.002168"
"25.50","1.70","18.36","0.002207"
"26.00","1.73","18.65","0.002241"
"26.50","1.77","18.93","0.002277"
"27.00","1.80","19.22","0.002325"
"27.50","1.83","19.51","0.002357"
"28.00","1.87","19.80","0.002403"
"28.50","1.90","20.09","0.002445"
"29.00","1.93","20.38","0.002484"
"29.50","1.97","20.67","0.002527"
"30.00","2.00","20.96","0.002572"
"30.50","2.03","19.48","0.003084"
"31.00","2.07","19.68","0.003349"
"31.50","2.10","19.62","0.004140"
"32.00","2.13","19.41","0.005604"
"32.50","2.17","19.39","0.006938"
"33.00","2.20","19.40","0.008249"
"33.50","2.23","19.46","0.009457"
"34.00","2.27","19.39","0.01079"
"34.50","2.30","19.39","0.01208"
"35.00","2.33","19.43","0.01333"
"35.50","2.37","19.41","0.01459"
"36.00","2.40","19.44","0.01532"
"36.50","2.43","19.42","0.01566"
"37.00","2.47","19.41","0.01582"
"37.50","2.50","19.53","0.01593"
"38.00","2.53","19.88","0.01617"
"38.50","2.57","20.13","0.01662"
"39.00","2.60","20.33","0.01712"
"39.50","2.63","20.51","0.01764"
"40.00","2.67","20.68","0.01816"
"40.50","2.70","20.84","0.01866"
"41.00","2.73","20.99","0.01915"
"41.50","2.77","21.13","0.01960"
"42.00","2.80","21.27","0.02004"
"42.50","2.83","21.39","0.02048"
"43.00","2.87","21.52","0.02090"
"43.50","2.90","21.65","0.02135"
"44.00","2.93","21.77","0.02177"
"44.50","2.97","21.89","0.02218"
"45.00","3.00","22.01","0.02261"
"45.50","3.03","22.13","0.02305"
"46.00","3.07","22.26","0.02346"
"46.50","3.10","22.37","0.02390"
"47.00","3.13","22.49","0.02433"
"47.50","3.17","22.61","0.02478"
"48.00","3.20","22.72","0.02522"
"48.50","3.23","22.83","0.02567"
"49.00","3.27","22.95","0.02611"
"49.50","3.30","23.06","0.02656"
"50.00","3.33","23.17","0.02702"
"50.50","3.37","23.28","0.02748"
"51.00","3.40","23.38","0.02793"
"51.50","3.43","23.49","0.02839"
"52.00","3.47","23.60","0.02885"
"52.50","3.50","23.71","0.02932"
"53.00","3.53","23.81","0.02979"
"53.50","3.57","23.91","0.03027"
"54.00","3.60","24.01","0.03073"
"54.50","3.63","24.12","0.03121"
"55.00","3.67","24.22","0.03170"
"55.50","3.70","24.31","0.03219"
"56.00","3.73","24.41","0.03268"
"56.50","3.77","24.51","0.03315"
"57.00","3.80","24.60","0.03365"
"57.50","3.83","24.70","0.03415"
"58.00","3.87","24.79","0.03464"
"58.50","3.90","24.89","0.03516"
"59.00","3.93","24.98","0.03565"
"59.50","3.97","25.07","0.03617"
"60.00","4.00","25.16","0.03667"
"60.50","4.03","25.24","0.03719"
"61.00","4.07","25.33","0.03770"
"61.50","4.10","25.42","0.03822"
"62.00","4.13","25.50","0.03876"
"62.50","4.17","25.58","0.03927"
"63.00","4.20","25.67","0.03982"
"63.50","4.23","25.75","0.04035"
"64.00","4.27","25.83","0.04089"
"64.50","4.30","25.91","0.04142"
"65.00","4.33","25.98","0.04197"
"65.50","4.37","26.06","0.04252"
"66.00","4.40","26.14","0.04308"
"66.50","4.43","26.21","0.04363"
"67.00","4.47","26.28","0.04418"
"67.50","4.50","26.36","0.04474"
"68.00","4.53","26.43","0.04530"
"68.50","4.57","26.50","0.04587"
"69.00","4.60","26.56","0.04644"
"69.50","4.63","26.63","0.04701"
"70.00","4.67","26.70","0.04759"
"70.50","4.70","26.76","0.04817"
"71.00","4.73","26.82","0.04875"
"71.50","4.77","26.89","0.04933"
"72.00","4.80","26.95","0.04992"
"72.50","4.83","27.01","0.05051"
"73.00","4.87","27.07","0.05111"
"73.50","4.90","27.13","0.05170"
"74.00","4.93","27.18","0.05231"
"74.50","4.97","27.24","0.05290"
"75.00","5.00","27.29","0.05352"
"75.50","5.03","27.35","0.05414"
"76.00","5.07","27.40","0.05474"
"76.50","5.10","27.45","0.05536"
"77.00","5.13","27.51","0.05599"
"77.50","5.17","27.56","0.05660"
"78.00","5.20","27.61","0.05723"
"78.50","5.23","27.65","0.05786"
"79.00","5.27","27.70","0.05849"
"79.50","5.30","27.75","0.05912"
"80.00","5.33","27.80","0.05977"
"80.50","5.37","27.84","0.06041"
"81.00","5.40","27.88","0.06105"
"81.50","5.43","27.93","0.06169"
"82.00","5.47","27.97","0.06234"
"82.50","5.50","28.01","0.06300"
"83.00","5.53","28.05","0.06365"
"83.50","5.57","28.09","0.06432"
"84.00","5.60","28.13","0.06498"
"84.50","5.63","28.17","0.06563"
"85.00","5.67","28.21","0.06631"
"85.50","5.70","28.24","0.06697"
"86.00","5.73","28.28","0.06764"
"86.50","5.77","28.32","0.06832"
"87.00","5.80","28.35","0.06899"
"87.50","5.83","28.38","0.06967"
"88.00","5.87","28.42","0.07035"
"88.50","5.90","28.45","0.07105"
"89.00","5.93","28.48","0.07173"
"89.50","5.97","28.51","0.07243"
"90.00","6.00","28.54","0.07313"
"90.50","6.03","28.57","0.07382"
"91.00","6.07","28.60","0.07454"
"91.50","6.10","28.63","0.07523"
"92.00","6.13","28.65","0.07595"
"92.50","6.17","28.68","0.07666"
"93.00","6.20","28.70","0.07738"
"93.50","6.23","28.73","0.07808"
"94.00","6.27","28.75","0.07881"
"94.50","6.30","28.78","0.07953"
"95.00","6.33","28.80","0.08025"
"95.50","6.37","28.82","0.08098"
"96.00","6.40","28.85","0.08172"
"96.50","6.43","28.87","0.08245"
"97.00","6.47","28.89","0.08319"
"97.50","6.50","28.91","0.08393"
"98.00","6.53","28.93","0.08468"
"98.50","6.57","28.95","0.08542"
"99.00","6.60","28.97","0.08617"
"99.50","6.63","28.99","0.08692"
"100.00","6.67","29.01","0.08767"
"100.50","6.70","29.02","0.08843"
"101.00","6.73","29.04","0.08920"
"101.50","6.77","29.05","0.08995"
"102.00","6.80","29.07","0.09070"
"102.50","6.83","29.09","0.09147"
"103.00","6.87","29.11","0.09224"
"103.50","6.90","29.12","0.09302"
"104.00","6.93","29.14","0.09379"
"104.50","6.97","29.15","0.09457"
"105.00","7.00","29.16","0.09536"
"105.50","7.03","29.18","0.09614"
"106.00","7.07","29.19","0.09692"
"106.50","7.10","29.20","0.09771"
"107.00","7.13","29.22","0.09851"
"107.50","7.17","29.23","0.09931"
"108.00","7.20","29.24","0.1001"
"108.50","7.23","29.25","0.1009"
"109.00","7.27","29.26","0.1017"
"109.50","7.30","29.27","0.1025"
"110.00","7.33","29.28","0.1033"
"110.50","7.37","29.29","0.1041"
"111.00","7.40","29.30","0.1049"
"111.50","7.43","29.31","0.1058"
"112.00","7.47","29.32","0.1066"
"112.50","7.50","29.33","0.1074"
"113.00","7.53","29.34","0.1082"
"113.50","7.57","29.34","0.1090"
"114.00","7.60","29.35","0.1099"
"114.50","7.63","29.36","0.1107"
"115.00","7.67","29.36","0.1115"
"115.50","7.70","29.37","0.1124"
"116.00","7.73","29.37","0.1132"
"116.50","7.77","29.38","0.1141"
"117.00","7.80","29.38","0.1149"
"117.50","7.83","29.39","0.1158"
"118.00","7.87","29.40","0.1166"
"118.50","7.90","29.40","0.1175"
"119.00","7.93","29.40","0.1184"
"119.50","7.97","29.40","0.1192"
"120.00","8.00","29.41","0.1201"
"120.50","8.03","29.42","0.1209"
"121.00","8.07","29.42","0.1218"
"121.50","8.10","29.42","0.1227"
"122.00","8.13","29.42","0.1236"
"122.50","8.17","29.43","0.1245"
"123.00","8.20","29.43","0.1253"
"123.50","8.23","29.43","0.1262"
"124.00","8.27","29.44","0.1271"
"124.50","8.30","29.44","0.1280"
"125.00","8.33","29.44","0.1289"
"125.50","8.37","29.44","0.1298"
"126.00","8.40","29.44","0.1307"
"126.50","8.43","29.44","0.1316"
"127.00","8.47","29.44","0.1325"
"127.50","8.50","29.44","0.1334"
"128.00","8.53","29.44","0.1343"
"128.50","8.57","29.44","0.1353"
"129.00","8.60","29.44","0.1362"
"129.50","8.63","29.44","0.1371"
"130.00","8.67","29.44","0.1380"
"130.50","8.70","29.44","0.1390"
"131.00","8.73","29.44","0.1399"
"131.50","8.77","29.44","0.1408"
"132.00","8.80","29.44","0.1418"
"132.50","8.83","29.44","0.1427"
"133.00","8.87","29.44","0.1437"
"133.50","8.90","29.43","0.1446"
"134.00","8.93","29.43","0.1456"
"134.50","8.97","29.43","0.1465"
"135.00","9.00","29.43","0.1475"
"135.50","9.03","29.42","0.1485"
"136.00","9.07","29.42","0.1494"
"136.50","9.10","29.42","0.1504"
"137.00","9.13","29.42","0.1514"
"137.50","9.17","29.41","0.1524"
"138.00","9.20","29.40","0.1534"
"138.50","9.23","29.40","0.1544"
"139.00","9.27","29.39","0.1554"
"139.50","9.30","29.39","0.1564"
"140.00","9.33","29.39","0.1574"
"140.50","9.37","29.38","0.1584"
"141.00","9.40","29.38","0.1594"
"141.50","9.43","29.37","0.1604"
"142.00","9.47","29.37","0.1615"
"142.50","9.50","29.36","0.1625"
"143.00","9.53","29.36","0.1635"
"143.50","9.57","29.35","0.1646"
"144.00","9.60","29.35","0.1657"
"144.50","9.63","29.34","0.1667"
"145.00","9.67","29.33","0.1678"
"145.50","9.70","29.33","0.1689"
"146.00","9.73","29.32","0.1700"
"146.50","9.77","29.31","0.1710"
"147.00","9.80","29.31","0.1721"
"147.50","9.83","29.30","0.1732"
"148.00","9.87","29.29","0.1743"
"148.50","9.90","29.28","0.1754"
"149.00","9.93","29.27","0.1766"
"149.50","9.97","29.26","0.1777"
"150.00","10.00","29.26","0.1788"
"150.50","10.03","29.24","0.1800"
"151.00","10.07","29.23","0.1811"
"151.50","10.10","29.22","0.1823"
"152.00","10.13","29.21","0.1834"
"152.50","10.17","29.20","0.1846"
"153.00","10.20","29.19","0.1858"
"153.50","10.23","29.17","0.1869"
"154.00","10.27","29.16","0.1881"
"154.50","10.30","29.14","0.1893"
"155.00","10.33","29.13","0.1905"
"155.50","10.37","29.11","0.1917"
"156.00","10.40","29.09","0.1930"
"156.50","10.43","29.07","0.1942"
"157.00","10.47","29.05","0.1954"
"157.50","10.50","29.03","0.1967"
"158.00","10.53","29.01","0.1979"
"158.50","10.57","28.99","0.1992"
"159.00","10.60","28.96","0.2005"
"159.50","10.63","28.93","0.2017"
"160.00","10.67","28.90","0.2030"
"160.50","10.70","28.87","0.2043"
"161.00","10.73","28.84","0.2056"
"161.50","10.77","28.81","0.2069"
"162.00","10.80","28.77","0.2082"
"162.50","10.83","28.74","0.2095"
"163.00","10.87","28.70","0.2108"
"163.50","10.90","28.66","0.2121"
"164.00","10.93","28.62","0.2135"
"164.50","10.97","28.58","0.2148"
"165.00","11.00","28.53","0.2161"
"165.50","11.03","28.49","0.2174"
"166.00","11.07","28.44","0.2188"
"166.50","11.10","28.39","0.2201"
"167.00","11.13","28.34","0.2215"
"167.50","11.17","28.29","0.2228"
"168.00","11.20","28.24","0.2241"
"168.50","11.23","28.18","0.2255"
"169.00","11.27","28.12","0.2269"
"169.50","11.30","28.06","0.2282"
"170.00","11.33","28.01","0.2296"
"170.50","11.37","27.94","0.2309"
"171.00","11.40","27.88","0.2323"
"171.50","11.43","27.82","0.2336"
"172.00","11.47","27.75","0.2350"
"172.50","11.50","27.69","0.2363"
"173.00","11.53","27.62","0.2377"
"173.50","11.57","27.55","0.2390"
"174.00","11.60","27.48","0.2404"
"174.50","11.63","27.40","0.2418"
"175.00","11.67","27.33","0.2431"
"175.50","11.70","27.25","0.2445"
"176.00","11.73","27.17","0.2459"
"176.50","11.77","27.09","0.2472"
"177.00","11.80","27.01","0.2486"
"177.50","11.83","26.93","0.2500"
"178.00","11.87","26.84","0.2514"
"178.50","11.90","26.75","0.2528"
"179.00","11.93","26.66","0.2541"
"179.50","11.97","26.57","0.2555"
"180.00","12.00","26.48","0.2569"
"180.50","12.03","26.38","0.2583"
"181.00","12.07","26.29","0.2597"
"181.50","12.10","26.19","0.2611"
"182.00","12.13","26.09","0.2625"
"182.50","12.17","25.98","0.2639"
"183.00","12.20","25.88","0.2653"
"183.50","12.23","25.78","0.2667"
"184.00","12.27","25.67","0.2681"
"184.50","12.30","25.56","0.2695"
"185.00","12.33","25.45","0.2709"
"185.50","12.37","25.33","0.2723"
"186.00","12.40","25.22","0.2737"
"186.50","12.43","25.09","0.2752"
"187.00","12.47","24.97","0.2766"
"187.50","12.50","24.85","0.2780"
"188.00","12.53","24.72","0.2794"
"188.50","12.57","24.60","0.2809"
"189.00","12.60","24.46","0.2823"
"189.50","12.63","24.33","0.2837"
"190.00","12.67","24.19","0.2852"
"190.50","12.70","24.05","0.2866"
"191.00","12.73","23.91","0.2881"
"191.50","12.77","23.76","0.2895"
"192.00","12.80","23.62","0.2910"
"192.50","12.83","23.47","0.2924"
"193.00","12.87","23.31","0.2939"
"193.50","12.90","23.15","0.2953"
"194.00","12.93","22.99","0.2968"
"194.50","12.97","22.82","0.2983"
"195.00","13.00","22.65","0.2997"
"195.50","13.03","22.48","0.3012"
"196.00","13.07","22.29","0.3027"
"196.50","13.10","22.11","0.3042"
"197.00","13.13","21.91","0.3057"
"197.31","13.15","12.85","0.3031"