File: L2D/N02D304_1.csv
System ID,,"4483C1713"
Method name only,,"Tension_Round_NEW"
Test type,,"Tension"
Sample file name,,"N02D304"
Last test date,,"9/15/2025"
Last test time,,"5:19:03 PM"
Course,,"NPRE432"
Lab Section Number,,"02"
Group,,"D"
Material,,"304 Stainless Steel"
Heat Treatment,,""
Other Information,,""
Crosshead Speed,(mm/min),"4.00"
Geometry,,"Circular"
Gage Diameter,(mm),"7.03"
Grip Diameter,(mm),"12.60"
Rockwell Hardness,,"99.6"
Rockwell Scale,,"HRB"
Extensometer Gage Length,(mm),"25.40"
Final Gage Diameter,(mm),"3.33"
Fracture Notes and Location,,""
Notes During Test,,""

Results Table 1
,,"1"
Maximum Force,(kN),"28.31"
Maximum Strain,(%),"60.95"

Time,Displacement,Force,Strain 1
(s),(mm),(kN),(mm/mm)
"0.00","0.00","0.1394","0.000002853"
"0.50","0.03","1.017","0.00009085"
"1.00","0.07","2.034","0.0002226"
"1.50","0.10","2.954","0.0003682"
"2.00","0.13","3.738","0.0004881"
"2.50","0.17","4.425","0.0005953"
"3.00","0.20","5.032","0.0006892"
"3.50","0.23","5.519","0.0007847"
"4.00","0.27","5.967","0.0008652"
"4.50","0.30","6.390","0.0009388"
"5.00","0.33","6.793","0.001017"
"5.50","0.37","7.188","0.001093"
"6.00","0.40","7.568","0.001174"
"6.50","0.43","7.934","0.001242"
"7.00","0.47","8.299","0.001316"
"7.50","0.50","8.657","0.001388"
"8.00","0.53","9.006","0.001461"
"8.50","0.57","9.357","0.001537"
"9.00","0.60","9.702","0.001599"
"9.50","0.63","10.05","0.001683"
"10.00","0.67","10.39","0.001755"
"10.50","0.70","10.74","0.001837"
"11.00","0.73","11.10","0.001929"
"11.50","0.77","11.45","0.002017"
"12.00","0.80","11.80","0.002095"
"12.50","0.83","12.14","0.002192"
"13.00","0.87","12.49","0.002293"
"13.50","0.90","12.83","0.002384"
"14.00","0.93","13.13","0.002489"
"14.50","0.97","13.48","0.002597"
"15.00","1.00","13.80","0.002696"
"15.50","1.03","14.12","0.002813"
"16.00","1.07","14.43","0.002912"
"16.50","1.10","14.73","0.003026"
"17.00","1.13","15.01","0.003132"
"17.50","1.17","15.29","0.003239"
"18.00","1.20","15.57","0.003349"
"18.50","1.23","15.84","0.003475"
"19.00","1.27","16.12","0.003587"
"19.50","1.30","16.39","0.003728"
"20.00","1.33","16.67","0.003851"
"20.50","1.37","16.94","0.003977"
"21.00","1.40","17.22","0.004137"
"21.50","1.43","17.47","0.004283"
"22.00","1.47","17.75","0.004425"
"22.50","1.50","18.02","0.004575"
"23.00","1.53","18.28","0.004744"
"23.50","1.57","18.54","0.004923"
"24.00","1.60","18.80","0.005106"
"24.50","1.63","19.05","0.005283"
"25.00","1.67","19.31","0.005481"
"25.50","1.70","19.56","0.005697"
"26.00","1.73","19.80","0.005923"
"26.50","1.77","20.03","0.006131"
"27.00","1.80","20.27","0.006381"
"27.50","1.83","20.50","0.006635"
"28.00","1.87","20.72","0.006907"
"28.50","1.90","20.93","0.007196"
"29.00","1.93","21.14","0.007504"
"29.50","1.97","21.34","0.007836"
"30.00","2.00","21.53","0.008192"
"30.50","2.03","21.71","0.008560"
"31.00","2.07","21.88","0.008971"
"31.50","2.10","22.03","0.009429"
"32.00","2.13","22.17","0.009900"
"32.50","2.17","22.31","0.01042"
"33.00","2.20","22.42","0.01097"
"33.50","2.23","22.52","0.01156"
"34.00","2.27","22.62","0.01219"
"34.50","2.30","22.69","0.01285"
"35.00","2.33","22.76","0.01354"
"35.50","2.37","22.83","0.01424"
"36.00","2.40","22.89","0.01499"
"36.50","2.43","22.95","0.01575"
"37.00","2.47","23.00","0.01654"
"37.50","2.50","23.04","0.01732"
"38.00","2.53","23.09","0.01813"
"38.50","2.57","23.13","0.01893"
"39.00","2.60","23.17","0.01974"
"39.50","2.63","23.20","0.02058"
"40.00","2.67","23.24","0.02140"
"40.50","2.70","23.27","0.02224"
"41.00","2.73","23.31","0.02307"
"41.50","2.77","23.34","0.02391"
"42.00","2.80","23.37","0.02476"
"42.50","2.83","23.41","0.02560"
"43.00","2.87","23.43","0.02645"
"43.50","2.90","23.46","0.02729"
"44.00","2.93","23.49","0.02812"
"44.50","2.97","23.52","0.02898"
"45.00","3.00","23.55","0.02982"
"45.50","3.03","23.58","0.03066"
"46.00","3.07","23.60","0.03150"
"46.50","3.10","23.63","0.03234"
"47.00","3.13","23.66","0.03319"
"47.50","3.17","23.69","0.03403"
"48.00","3.20","23.71","0.03486"
"48.50","3.23","23.74","0.03570"
"49.00","3.27","23.76","0.03653"
"49.50","3.30","23.79","0.03736"
"50.00","3.33","23.81","0.03820"
"50.50","3.37","23.84","0.03902"
"51.00","3.40","23.87","0.03985"
"51.50","3.43","23.89","0.04067"
"52.00","3.47","23.92","0.04150"
"52.50","3.50","23.94","0.04235"
"53.00","3.53","23.96","0.04316"
"53.50","3.57","23.99","0.04398"
"54.00","3.60","24.01","0.04480"
"54.50","3.63","24.03","0.04563"
"55.00","3.67","24.05","0.04646"
"55.50","3.70","24.08","0.04729"
"56.00","3.73","24.10","0.04810"
"56.50","3.77","24.12","0.04893"
"57.00","3.80","24.14","0.04976"
"57.50","3.83","24.16","0.05059"
"58.00","3.87","24.19","0.05139"
"58.50","3.90","24.21","0.05221"
"59.00","3.93","24.23","0.05303"
"59.50","3.97","24.25","0.05384"
"60.00","4.00","24.27","0.05467"
"60.50","4.03","24.29","0.05548"
"61.00","4.07","24.31","0.05629"
"61.50","4.10","24.33","0.05712"
"62.00","4.13","24.35","0.05793"
"62.50","4.17","24.37","0.05875"
"63.00","4.20","24.40","0.05956"
"63.50","4.23","24.41","0.06038"
"64.00","4.27","24.44","0.06118"
"64.50","4.30","24.45","0.06199"
"65.00","4.33","24.47","0.06282"
"65.50","4.37","24.50","0.06363"
"66.00","4.40","24.51","0.06444"
"66.50","4.43","24.53","0.06526"
"67.00","4.47","24.55","0.06606"
"67.50","4.50","24.57","0.06687"
"68.00","4.53","24.59","0.06768"
"68.50","4.57","24.61","0.06849"
"69.00","4.60","24.63","0.06930"
"69.50","4.63","24.65","0.07011"
"70.00","4.67","24.67","0.07091"
"70.50","4.70","24.69","0.07172"
"71.00","4.73","24.71","0.07252"
"71.50","4.77","24.72","0.07333"
"72.00","4.80","24.74","0.07413"
"72.50","4.83","24.77","0.07494"
"73.00","4.87","24.78","0.07574"
"73.50","4.90","24.80","0.07655"
"74.00","4.93","24.82","0.07735"
"74.50","4.97","24.84","0.07815"
"75.00","5.00","24.86","0.07895"
"75.50","5.03","24.88","0.07977"
"76.00","5.07","24.89","0.08058"
"76.50","5.10","24.91","0.08138"
"77.00","5.13","24.93","0.08219"
"77.50","5.17","24.95","0.08300"
"78.00","5.20","24.96","0.08380"
"78.50","5.23","24.98","0.08460"
"79.00","5.27","25.00","0.08541"
"79.50","5.30","25.01","0.08622"
"80.00","5.33","25.03","0.08702"
"80.50","5.37","25.05","0.08782"
"81.00","5.40","25.07","0.08863"
"81.50","5.43","25.09","0.08944"
"82.00","5.47","25.10","0.09024"
"82.50","5.50","25.12","0.09105"
"83.00","5.53","25.13","0.09185"
"83.50","5.57","25.15","0.09266"
"84.00","5.60","25.17","0.09347"
"84.50","5.63","25.18","0.09427"
"85.00","5.67","25.20","0.09508"
"85.50","5.70","25.22","0.09589"
"86.00","5.73","25.23","0.09668"
"86.50","5.77","25.25","0.09750"
"87.00","5.80","25.27","0.09829"
"87.50","5.83","25.28","0.09909"
"88.00","5.87","25.30","0.09990"
"88.50","5.90","25.32","0.1007"
"89.00","5.93","25.33","0.1015"
"89.50","5.97","25.35","0.1023"
"90.00","6.00","25.37","0.1031"
"90.50","6.03","25.38","0.1039"
"91.00","6.07","25.40","0.1047"
"91.50","6.10","25.41","0.1055"
"92.00","6.13","25.43","0.1063"
"92.50","6.17","25.45","0.1072"
"93.00","6.20","25.46","0.1080"
"93.50","6.23","25.48","0.1088"
"94.00","6.27","25.49","0.1096"
"94.50","6.30","25.51","0.1104"
"95.00","6.33","25.53","0.1112"
"95.50","6.37","25.54","0.1120"
"96.00","6.40","25.56","0.1128"
"96.50","6.43","25.57","0.1136"
"97.00","6.47","25.59","0.1144"
"97.50","6.50","25.60","0.1152"
"98.00","6.53","25.62","0.1160"
"98.50","6.57","25.63","0.1168"
"99.00","6.60","25.65","0.1176"
"99.50","6.63","25.66","0.1184"
"100.00","6.67","25.68","0.1192"
"100.50","6.70","25.69","0.1200"
"101.00","6.73","25.70","0.1208"
"101.50","6.77","25.72","0.1216"
"102.00","6.80","25.74","0.1225"
"102.50","6.83","25.75","0.1233"
"103.00","6.87","25.76","0.1241"
"103.50","6.90","25.78","0.1249"
"104.00","6.93","25.79","0.1257"
"104.50","6.97","25.81","0.1265"
"105.00","7.00","25.82","0.1273"
"105.50","7.03","25.83","0.1281"
"106.00","7.07","25.85","0.1289"
"106.50","7.10","25.86","0.1297"
"107.00","7.13","25.87","0.1305"
"107.50","7.17","25.89","0.1313"
"108.00","7.20","25.90","0.1321"
"108.50","7.23","25.92","0.1329"
"109.00","7.27","25.93","0.1337"
"109.50","7.30","25.94","0.1345"
"110.00","7.33","25.96","0.1353"
"110.50","7.37","25.97","0.1362"
"111.00","7.40","25.99","0.1370"
"111.50","7.43","26.00","0.1378"
"112.00","7.47","26.01","0.1386"
"112.50","7.50","26.03","0.1394"
"113.00","7.53","26.04","0.1402"
"113.50","7.57","26.06","0.1410"
"114.00","7.60","26.07","0.1418"
"114.50","7.63","26.08","0.1426"
"115.00","7.67","26.10","0.1434"
"115.50","7.70","26.11","0.1442"
"116.00","7.73","26.12","0.1450"
"116.50","7.77","26.14","0.1458"
"117.00","7.80","26.15","0.1466"
"117.50","7.83","26.16","0.1474"
"118.00","7.87","26.18","0.1482"
"118.50","7.90","26.19","0.1490"
"119.00","7.93","26.20","0.1498"
"119.50","7.97","26.21","0.1506"
"120.00","8.00","26.23","0.1514"
"120.50","8.03","26.24","0.1522"
"121.00","8.07","26.25","0.1531"
"121.50","8.10","26.26","0.1538"
"122.00","8.13","26.28","0.1547"
"122.50","8.17","26.29","0.1555"
"123.00","8.20","26.30","0.1563"
"123.50","8.23","26.31","0.1571"
"124.00","8.27","26.32","0.1579"
"124.50","8.30","26.34","0.1587"
"125.00","8.33","26.35","0.1595"
"125.50","8.37","26.36","0.1603"
"126.00","8.40","26.37","0.1611"
"126.50","8.43","26.39","0.1619"
"127.00","8.47","26.40","0.1627"
"127.50","8.50","26.41","0.1635"
"128.00","8.53","26.42","0.1643"
"128.50","8.57","26.43","0.1651"
"129.00","8.60","26.45","0.1659"
"129.50","8.63","26.46","0.1667"
"130.00","8.67","26.47","0.1676"
"130.50","8.70","26.48","0.1683"
"131.00","8.73","26.49","0.1692"
"131.50","8.77","26.50","0.1700"
"132.00","8.80","26.52","0.1708"
"132.50","8.83","26.53","0.1716"
"133.00","8.87","26.54","0.1724"
"133.50","8.90","26.55","0.1732"
"134.00","8.93","26.56","0.1740"
"134.50","8.97","26.58","0.1748"
"135.00","9.00","26.59","0.1756"
"135.50","9.03","26.60","0.1764"
"136.00","9.07","26.61","0.1773"
"136.50","9.10","26.62","0.1781"
"137.00","9.13","26.63","0.1789"
"137.50","9.17","26.64","0.1797"
"138.00","9.20","26.66","0.1805"
"138.50","9.23","26.67","0.1813"
"139.00","9.27","26.68","0.1821"
"139.50","9.30","26.69","0.1829"
"140.00","9.33","26.70","0.1837"
"140.50","9.37","26.71","0.1845"
"141.00","9.40","26.72","0.1854"
"141.50","9.43","26.73","0.1862"
"142.00","9.47","26.74","0.1870"
"142.50","9.50","26.75","0.1878"
"143.00","9.53","26.76","0.1886"
"143.50","9.57","26.78","0.1894"
"144.00","9.60","26.78","0.1902"
"144.50","9.63","26.80","0.1911"
"145.00","9.67","26.81","0.1919"
"145.50","9.70","26.82","0.1927"
"146.00","9.73","26.83","0.1935"
"146.50","9.77","26.84","0.1943"
"147.00","9.80","26.85","0.1951"
"147.50","9.83","26.86","0.1959"
"148.00","9.87","26.87","0.1968"
"148.50","9.90","26.88","0.1976"
"149.00","9.93","26.89","0.1984"
"149.50","9.97","26.90","0.1992"
"150.00","10.00","26.91","0.2000"
"150.50","10.03","26.92","0.2009"
"151.00","10.07","26.93","0.2017"
"151.50","10.10","26.94","0.2025"
"152.00","10.13","26.95","0.2033"
"152.50","10.17","26.96","0.2041"
"153.00","10.20","26.97","0.2050"
"153.50","10.23","26.98","0.2058"
"154.00","10.27","26.99","0.2066"
"154.50","10.30","27.00","0.2074"
"155.00","10.33","27.01","0.2082"
"155.50","10.37","27.02","0.2091"
"156.00","10.40","27.03","0.2099"
"156.50","10.43","27.04","0.2107"
"157.00","10.47","27.05","0.2115"
"157.50","10.50","27.06","0.2123"
"158.00","10.53","27.07","0.2132"
"158.50","10.57","27.08","0.2140"
"159.00","10.60","27.09","0.2148"
"159.50","10.63","27.10","0.2157"
"160.00","10.67","27.11","0.2165"
"160.50","10.70","27.12","0.2173"
"161.00","10.73","27.13","0.2181"
"161.50","10.77","27.14","0.2190"
"162.00","10.80","27.15","0.2198"
"162.50","10.83","27.16","0.2206"
"163.00","10.87","27.17","0.2214"
"163.50","10.90","27.17","0.2223"
"164.00","10.93","27.18","0.2231"
"164.50","10.97","27.19","0.2239"
"165.00","11.00","27.20","0.2248"
"165.50","11.03","27.21","0.2256"
"166.00","11.07","27.22","0.2264"
"166.50","11.10","27.23","0.2273"
"167.00","11.13","27.24","0.2281"
"167.50","11.17","27.25","0.2289"
"168.00","11.20","27.25","0.2298"
"168.50","11.23","27.26","0.2306"
"169.00","11.27","27.27","0.2314"
"169.50","11.30","27.28","0.2323"
"170.00","11.33","27.29","0.2331"
"170.50","11.37","27.30","0.2339"
"171.00","11.40","27.31","0.2348"
"171.50","11.43","27.31","0.2356"
"172.00","11.47","27.33","0.2364"
"172.50","11.50","27.33","0.2373"
"173.00","11.53","27.34","0.2381"
"173.50","11.57","27.35","0.2390"
"174.00","11.60","27.36","0.2398"
"174.50","11.63","27.37","0.2407"
"175.00","11.67","27.37","0.2415"
"175.50","11.70","27.38","0.2423"
"176.00","11.73","27.39","0.2432"
"176.50","11.77","27.40","0.2440"
"177.00","11.80","27.41","0.2449"
"177.50","11.83","27.42","0.2457"
"178.00","11.87","27.42","0.2465"
"178.50","11.90","27.44","0.2474"
"179.00","11.93","27.44","0.2482"
"179.50","11.97","27.45","0.2491"
"180.00","12.00","27.46","0.2499"
"180.50","12.03","27.47","0.2507"
"181.00","12.07","27.47","0.2516"
"181.50","12.10","27.48","0.2524"
"182.00","12.13","27.49","0.2533"
"182.50","12.17","27.50","0.2541"
"183.00","12.20","27.51","0.2550"
"183.50","12.23","27.51","0.2558"
"184.00","12.27","27.52","0.2567"
"184.50","12.30","27.53","0.2575"
"185.00","12.33","27.54","0.2584"
"185.50","12.37","27.54","0.2592"
"186.00","12.40","27.55","0.2601"
"186.50","12.43","27.56","0.2609"
"187.00","12.47","27.56","0.2618"
"187.50","12.50","27.57","0.2626"
"188.00","12.53","27.58","0.2634"
"188.50","12.57","27.59","0.2643"
"189.00","12.60","27.59","0.2651"
"189.50","12.63","27.60","0.2660"
"190.00","12.67","27.61","0.2668"
"190.50","12.70","27.62","0.2677"
"191.00","12.73","27.62","0.2685"
"191.50","12.77","27.63","0.2694"
"192.00","12.80","27.64","0.2702"
"192.50","12.83","27.64","0.2711"
"193.00","12.87","27.65","0.2720"
"193.50","12.90","27.65","0.2728"
"194.00","12.93","27.66","0.2737"
"194.50","12.97","27.67","0.2745"
"195.00","13.00","27.68","0.2754"
"195.50","13.03","27.68","0.2763"
"196.00","13.07","27.69","0.2771"
"196.50","13.10","27.70","0.2780"
"197.00","13.13","27.71","0.2788"
"197.50","13.17","27.72","0.2797"
"198.00","13.20","27.72","0.2806"
"198.50","13.23","27.72","0.2814"
"199.00","13.27","27.73","0.2823"
"199.50","13.30","27.74","0.2831"
"200.00","13.33","27.75","0.2840"
"200.50","13.37","27.75","0.2849"
"201.00","13.40","27.76","0.2857"
"201.50","13.43","27.77","0.2866"
"202.00","13.47","27.77","0.2875"
"202.50","13.50","27.78","0.2883"
"203.00","13.53","27.79","0.2892"
"203.50","13.57","27.79","0.2901"
"204.00","13.60","27.80","0.2910"
"204.50","13.63","27.81","0.2918"
"205.00","13.67","27.81","0.2927"
"205.50","13.70","27.82","0.2936"
"206.00","13.73","27.82","0.2944"
"206.50","13.77","27.83","0.2953"
"207.00","13.80","27.83","0.2962"
"207.50","13.83","27.84","0.2971"
"208.00","13.87","27.84","0.2979"
"208.50","13.90","27.85","0.2988"
"209.00","13.93","27.86","0.2997"
"209.50","13.97","27.86","0.3006"
"210.00","14.00","27.87","0.3014"
"210.50","14.03","27.87","0.3023"
"211.00","14.07","27.88","0.3032"
"211.50","14.10","27.89","0.3041"
"212.00","14.13","27.89","0.3050"
"212.50","14.17","27.89","0.3058"
"213.00","14.20","27.90","0.3067"
"213.50","14.23","27.91","0.3076"
"214.00","14.27","27.91","0.3085"
"214.50","14.30","27.92","0.3094"
"215.00","14.33","27.93","0.3103"
"215.50","14.37","27.93","0.3112"
"216.00","14.40","27.94","0.3121"
"216.50","14.43","27.94","0.3130"
"217.00","14.47","27.94","0.3139"
"217.50","14.50","27.95","0.3148"
"218.00","14.53","27.96","0.3157"
"218.50","14.57","27.96","0.3166"
"219.00","14.60","27.97","0.3175"
"219.50","14.63","27.97","0.3184"
"220.00","14.67","27.98","0.3192"
"220.50","14.70","27.99","0.3202"
"221.00","14.73","27.99","0.3211"
"221.50","14.77","28.00","0.3220"
"222.00","14.80","28.00","0.3229"
"222.50","14.83","28.00","0.3238"
"223.00","14.87","28.01","0.3247"
"223.50","14.90","28.02","0.3256"
"224.00","14.93","28.02","0.3265"
"224.50","14.97","28.03","0.3274"
"225.00","15.00","28.03","0.3283"
"225.50","15.03","28.03","0.3292"
"226.00","15.07","28.04","0.3301"
"226.50","15.10","28.04","0.3311"
"227.00","15.13","28.05","0.3320"
"227.50","15.17","28.05","0.3329"
"228.00","15.20","28.06","0.3338"
"228.50","15.23","28.06","0.3347"
"229.00","15.27","28.07","0.3356"
"229.50","15.30","28.07","0.3366"
"230.00","15.33","28.07","0.3375"
"230.50","15.37","28.08","0.3384"
"231.00","15.40","28.09","0.3393"
"231.50","15.43","28.09","0.3403"
"232.00","15.47","28.09","0.3412"
"232.50","15.50","28.09","0.3421"
"233.00","15.53","28.10","0.3430"
"233.50","15.57","28.11","0.3440"
"234.00","15.60","28.11","0.3449"
"234.50","15.63","28.11","0.3458"
"235.00","15.67","28.12","0.3468"
"235.50","15.70","28.12","0.3477"
"236.00","15.73","28.13","0.3487"
"236.50","15.77","28.13","0.3496"
"237.00","15.80","28.14","0.3505"
"237.50","15.83","28.14","0.3515"
"238.00","15.87","28.14","0.3524"
"238.50","15.90","28.15","0.3534"
"239.00","15.93","28.15","0.3543"
"239.50","15.97","28.12","0.3552"
"240.00","16.00","28.16","0.3561"
"240.50","16.03","28.16","0.3570"
"241.00","16.07","28.17","0.3580"
"241.50","16.10","28.17","0.3589"
"242.00","16.13","28.18","0.3599"
"242.50","16.17","28.18","0.3609"
"243.00","16.20","28.18","0.3618"
"243.50","16.23","28.18","0.3628"
"244.00","16.27","28.19","0.3637"
"244.50","16.30","28.19","0.3647"
"245.00","16.33","28.20","0.3656"
"245.50","16.37","28.20","0.3666"
"246.00","16.40","28.20","0.3676"
"246.50","16.43","28.20","0.3685"
"247.00","16.47","28.21","0.3695"
"247.50","16.50","28.21","0.3705"
"248.00","16.53","28.21","0.3714"
"248.50","16.57","28.22","0.3724"
"249.00","16.60","28.22","0.3734"
"249.50","16.63","28.22","0.3744"
"250.00","16.67","28.23","0.3753"
"250.50","16.70","28.23","0.3763"
"251.00","16.73","28.23","0.3773"
"251.50","16.77","28.23","0.3783"
"252.00","16.80","28.24","0.3793"
"252.50","16.83","28.24","0.3802"
"253.00","16.87","28.24","0.3812"
"253.50","16.90","28.24","0.3822"
"254.00","16.93","28.25","0.3832"
"254.50","16.97","28.25","0.3842"
"255.00","17.00","28.25","0.3852"
"255.50","17.03","28.25","0.3862"
"256.00","17.07","28.25","0.3871"
"256.50","17.10","28.26","0.3882"
"257.00","17.13","28.26","0.3891"
"257.50","17.17","28.26","0.3901"
"258.00","17.20","28.26","0.3912"
"258.50","17.23","28.27","0.3921"
"259.00","17.27","28.27","0.3932"
"259.50","17.30","28.27","0.3942"
"260.00","17.33","28.27","0.3952"
"260.50","17.37","28.28","0.3962"
"261.00","17.40","28.28","0.3972"
"261.50","17.43","28.28","0.3982"
"262.00","17.47","28.28","0.3992"
"262.50","17.50","28.28","0.4003"
"263.00","17.53","28.29","0.4013"
"263.50","17.57","28.29","0.4023"
"264.00","17.60","28.29","0.4033"
"264.50","17.63","28.29","0.4044"
"265.00","17.67","28.29","0.4054"
"265.50","17.70","28.30","0.4064"
"266.00","17.73","28.30","0.4075"
"266.50","17.77","28.30","0.4085"
"267.00","17.80","28.30","0.4095"
"267.50","17.83","28.30","0.4106"
"268.00","17.87","28.30","0.4117"
"268.50","17.90","28.30","0.4127"
"269.00","17.93","28.30","0.4137"
"269.50","17.97","28.30","0.4148"
"270.00","18.00","28.30","0.4158"
"270.50","18.03","28.30","0.4169"
"271.00","18.07","28.30","0.4179"
"271.50","18.10","28.31","0.4190"
"272.00","18.13","28.30","0.4201"
"272.50","18.17","28.30","0.4211"
"273.00","18.20","28.30","0.4222"
"273.50","18.23","28.30","0.4233"
"274.00","18.27","28.30","0.4244"
"274.50","18.30","28.31","0.4254"
"275.00","18.33","28.30","0.4265"
"275.50","18.37","28.30","0.4276"
"276.00","18.40","28.30","0.4287"
"276.50","18.43","28.30","0.4298"
"277.00","18.47","28.30","0.4309"
"277.50","18.50","28.30","0.4320"
"278.00","18.53","28.30","0.4331"
"278.50","18.57","28.30","0.4342"
"279.00","18.60","28.30","0.4354"
"279.50","18.63","28.30","0.4365"
"280.00","18.67","28.30","0.4376"
"280.50","18.70","28.30","0.4387"
"281.00","18.73","28.30","0.4399"
"281.50","18.77","28.29","0.4410"
"282.00","18.80","28.29","0.4421"
"282.50","18.83","28.29","0.4433"
"283.00","18.87","28.29","0.4444"
"283.50","18.90","28.28","0.4456"
"284.00","18.93","28.28","0.4467"
"284.50","18.97","28.28","0.4479"
"285.00","19.00","28.27","0.4490"
"285.50","19.03","28.27","0.4502"
"286.00","19.07","28.27","0.4514"
"286.50","19.10","28.26","0.4526"
"287.00","19.13","28.26","0.4537"
"287.50","19.17","28.25","0.4549"
"288.00","19.20","28.25","0.4561"
"288.50","19.23","28.25","0.4573"
"289.00","19.27","28.24","0.4585"
"289.50","19.30","28.23","0.4597"
"290.00","19.33","28.23","0.4609"
"290.50","19.37","28.22","0.4621"
"291.00","19.40","28.21","0.4633"
"291.50","19.43","28.21","0.4645"
"292.00","19.47","28.20","0.4657"
"292.50","19.50","28.19","0.4669"
"293.00","19.53","28.18","0.4682"
"293.50","19.57","28.17","0.4694"
"294.00","19.60","28.16","0.4706"
"294.50","19.63","28.15","0.4719"
"295.00","19.67","28.14","0.4731"
"295.50","19.70","28.13","0.4743"
"296.00","19.73","28.11","0.4756"
"296.50","19.77","28.10","0.4768"
"297.00","19.80","28.09","0.4781"
"297.50","19.83","28.08","0.4794"
"298.00","19.87","28.06","0.4806"
"298.50","19.90","28.04","0.4819"
"299.00","19.93","28.03","0.4832"
"299.50","19.97","28.01","0.4844"
"300.00","20.00","27.99","0.4857"
"300.50","20.03","27.97","0.4870"
"301.00","20.07","27.95","0.4883"
"301.50","20.10","27.93","0.4896"
"302.00","20.13","27.91","0.4909"
"302.50","20.17","27.89","0.4922"
"303.00","20.20","27.86","0.4935"
"303.50","20.23","27.84","0.4948"
"304.00","20.27","27.81","0.4961"
"304.50","20.30","27.78","0.4974"
"305.00","20.33","27.75","0.4987"
"305.50","20.37","27.72","0.5000"
"306.00","20.40","27.69","0.5014"
"306.50","20.43","27.66","0.5027"
"307.00","20.47","27.62","0.5040"
"307.50","20.50","27.59","0.5053"
"308.00","20.53","27.55","0.5067"
"308.50","20.57","27.51","0.5080"
"309.00","20.60","27.47","0.5093"
"309.50","20.63","27.43","0.5107"
"310.00","20.67","27.38","0.5120"
"310.50","20.70","27.34","0.5133"
"311.00","20.73","27.29","0.5147"
"311.50","20.77","27.24","0.5160"
"312.00","20.80","27.19","0.5174"
"312.50","20.83","27.14","0.5187"
"313.00","20.87","27.08","0.5201"
"313.50","20.90","27.02","0.5214"
"314.00","20.93","26.97","0.5228"
"314.50","20.97","26.90","0.5241"
"315.00","21.00","26.84","0.5255"
"315.50","21.03","26.78","0.5269"
"316.00","21.07","26.71","0.5282"
"316.50","21.10","26.64","0.5296"
"317.00","21.13","26.57","0.5310"
"317.50","21.17","26.49","0.5324"
"318.00","21.20","26.42","0.5337"
"318.50","21.23","26.34","0.5351"
"319.00","21.27","26.26","0.5365"
"319.50","21.30","26.18","0.5379"
"320.00","21.33","26.09","0.5392"
"320.50","21.37","26.00","0.5406"
"321.00","21.40","25.91","0.5420"
"321.50","21.43","25.82","0.5434"
"322.00","21.47","25.72","0.5448"
"322.50","21.50","25.63","0.5462"
"323.00","21.53","25.52","0.5476"
"323.50","21.57","25.42","0.5490"
"324.00","21.60","25.31","0.5504"
"324.50","21.63","25.20","0.5518"
"325.00","21.67","25.09","0.5533"
"325.50","21.70","24.97","0.5547"
"326.00","21.73","24.85","0.5561"
"326.50","21.77","24.73","0.5575"
"327.00","21.80","24.60","0.5590"
"327.50","21.83","24.47","0.5604"
"328.00","21.87","24.34","0.5618"
"328.50","21.90","24.20","0.5633"
"329.00","21.93","24.05","0.5647"
"329.50","21.97","23.91","0.5662"
"330.00","22.00","23.76","0.5676"
"330.50","22.03","23.61","0.5691"
"331.00","22.07","23.45","0.5706"
"331.50","22.10","23.28","0.5721"
"332.00","22.13","23.12","0.5736"
"332.50","22.17","22.95","0.5750"
"333.00","22.20","22.77","0.5765"
"333.50","22.23","22.59","0.5780"
"334.00","22.27","22.41","0.5795"
"334.50","22.30","22.22","0.5810"
"335.00","22.33","22.03","0.5825"
"335.50","22.37","21.83","0.5841"
"336.00","22.40","21.62","0.5856"
"336.50","22.43","21.41","0.5871"
"337.00","22.47","21.19","0.5887"
"337.50","22.50","20.98","0.5902"
"338.00","22.53","20.75","0.5918"
"338.50","22.57","20.52","0.5933"
"339.00","22.60","20.28","0.5949"
"339.50","22.63","20.03","0.5965"
"340.00","22.67","19.78","0.5981"
"340.50","22.70","19.52","0.5997"
"341.00","22.73","19.26","0.6013"
"341.50","22.77","18.98","0.6029"
"342.00","22.80","18.70","0.6045"
"342.50","22.83","18.41","0.6061"
"343.00","22.87","18.10","0.6078"
"343.50","22.90","17.75","0.6095"
"343.56","22.90","10.15","0.5941"